Python value cannot be used as a Z3 integer
Traceback (most recent call last):
  File "/home/conkas/conkas.py", line 108, in main
    traces = sym_exec.execute()
  File "/home/conkas/sym_exec/symbolic_executor.py", line 51, in execute
    new_traces = self.__sym_exec_traces(traces_to_execute)
  File "/home/conkas/sym_exec/symbolic_executor.py", line 64, in __sym_exec_traces
    new_blocks = self.__sym_exec_block(block_to_analyse, trace.state)
  File "/home/conkas/sym_exec/symbolic_executor.py", line 93, in __sym_exec_block
    new_blocks = self.__sym_exec_instruction(instruction, state)
  File "/home/conkas/sym_exec/symbolic_executor.py", line 116, in __sym_exec_instruction
    return func(instruction, state)
  File "/home/conkas/sym_exec/instructions/comparison.py", line 87, in inst_slt
    expr = If(a < b, BitVecVal(1, WORD_SIZE), BitVecVal(0, WORD_SIZE))
  File "/usr/local/lib/python3.8/dist-packages/z3/z3.py", line 3560, in __lt__
    a, b = _coerce_exprs(self, other)
  File "/usr/local/lib/python3.8/dist-packages/z3/z3.py", line 1114, in _coerce_exprs
    b = s.cast(b)
  File "/usr/local/lib/python3.8/dist-packages/z3/z3.py", line 3243, in cast
    return BitVecVal(val, self)
  File "/usr/local/lib/python3.8/dist-packages/z3/z3.py", line 3788, in BitVecVal
    return BitVecNumRef(Z3_mk_numeral(ctx.ref(), _to_int_str(val), bv.ast), ctx)
  File "/usr/local/lib/python3.8/dist-packages/z3/z3.py", line 2973, in _to_int_str
    _z3_assert(False, "Python value cannot be used as a Z3 integer")
  File "/usr/local/lib/python3.8/dist-packages/z3/z3.py", line 96, in _z3_assert
    raise Z3Exception(msg)
z3.z3types.Z3Exception: Python value cannot be used as a Z3 integer

real	0m6.251s
user	0m5.924s
sys	0m0.291s
