[INFO] | 2024-11-10 07:39:10 AM | analyzer.0x07c1c8c2bce6290daa554118b7d208041615ce54 | Analysis started at: 2024-11-10 07:39:10 AM
[INFO] | 2024-11-10 07:39:14 AM | analyzer.0x07c1c8c2bce6290daa554118b7d208041615ce54 | Version constraints: ['^0.4.19']
[INFO] | 2024-11-10 07:39:14 AM | analyzer.0x07c1c8c2bce6290daa554118b7d208041615ce54 | solc version: v0.4.19
[INFO] | 2024-11-10 07:39:17 AM | analyzer.0x07c1c8c2bce6290daa554118b7d208041615ce54 | Callgraph generation started!
[INFO] | 2024-11-10 07:39:17 AM | analyzer.0x07c1c8c2bce6290daa554118b7d208041615ce54 | Callgraph generation finished!
[INFO] | 2024-11-10 07:39:17 AM | analyzer.0x07c1c8c2bce6290daa554118b7d208041615ce54 | Interprocedural CFG generation started!
Traceback (most recent call last):
  File "/usr/local/lib/python3.6/dist-packages/networkx/classes/digraph.py", line 805, in successors
    return iter(self._succ[n])
KeyError: <basic_block.BasicBlock object at 0x7f7d359ef2b0>

The above exception was the direct cause of the following exception:

Traceback (most recent call last):
  File "contractlint.py", line 81, in analyze_contracts
    generated_icfg, icfg_objects = generate_icfg(slither_obj, callgraph, graph_dir, dump_graph, log)
  File "/root/sailfish/code/static_analysis/analysis/main_helper.py", line 412, in generate_icfg
    function_cfg = ICFG(slither_obj, contract, function, callgraph, graph_dir, dump_graph, log)
  File "/root/sailfish/code/static_analysis/analysis/icfg.py", line 54, in __init__
    self.setup()
  File "/root/sailfish/code/static_analysis/analysis/icfg.py", line 70, in setup
    compute_ancesters_decendents(self._function_icfg, self._leaf_nodes, self._root_nodes, self._all_predecessors, self._all_successors)
  File "/root/sailfish/code/static_analysis/analysis/util.py", line 188, in compute_ancesters_decendents
    get_all_successors_per_node(converted_graph, root_nodes, all_succs)
  File "/root/sailfish/code/static_analysis/analysis/util.py", line 261, in get_all_successors_per_node
    successors = list(graph.successors(node))
  File "/usr/local/lib/python3.6/dist-packages/networkx/classes/digraph.py", line 807, in successors
    raise NetworkXError(f"The node {n} is not in the digraph.") from e
networkx.exception.NetworkXError: The node "BlockID: 1648
Call context: buyTokensFor
None
END_IF None" is not in the digraph.

real	0m8.344s
user	0m9.384s
sys	0m2.805s
